Workbook

Sheet Calculateur
A2: Calculateur de criticité CVSS
B4: Version CVSS | C4: CVSS 3.1 | G4: SCORE / 10 | H4: Résultat
G5: Base | H5: =H17 -> 9.6
H6: =IF(H5=0,"Nul",IF(H5<4,"Faible",IF(H5<7,"Moyen",IF(H5<9,"Élevé","Critique")))) -> Critique
A7: Mode d’emploi | G7: Temporel | H7: =H18 -> 9.6
B8: 1. Choisir la version et les codes jaunes. | H8: =IF(H7=0,"Nul",IF(H7<4,"Faible",IF(H7<7,"Moyen",IF(H7<9,"Élevé","Critique")))) -> Critique
B9: 2. Lire les trois scores à droite. | G9: Environnemental | H9: =H25 -> 9.7
B10: 3. Consulter l’aide pour les codes. | H10: =IF(H9=0,"Nul",IF(H9<4,"Faible",IF(H9<7,"Moyen",IF(H9<9,"Élevé","Critique")))) -> Critique
A12: MÉTRIQUES DE BASE | G12: DÉTAIL DU CALCUL
A13: Code | B13: Critère | C13: Choix | D13: Effectif | E13: Poids
A14: AV | B14: Vecteur d’attaque | C14: N | D14: =C14 -> N | E14: =VLOOKUP("AV:"&D14,'Aide et coefficients'!$A$15:$C$65,2,FALSE()) -> 0.85 | G14: ISS | H14: =1-(1-E19)*(1-E20)*(1-E21) -> 0.914816
A15: AC | B15: Complexité | C15: L | D15: =C15 -> L | E15: =VLOOKUP("AC:"&D15,'Aide et coefficients'!$A$15:$C$65,2,FALSE()) -> 0.77 | G15: Impact | H15: =IF(D18="U",6.42*H14,7.52*(H14-0.029)-3.25*(H14-0.02)^15) -> 6.0477305
A16: PR | B16: Privilèges requis | C16: N | D16: =C16 -> N | E16: =VLOOKUP("PR:"&D18&":"&D16,'Aide et coefficients'!$A$15:$C$65,2,FALSE()) -> 0.85 | G16: Exploitabilité | H16: =8.22*E14*E15*E16*E17 -> 2.8352547
A17: UI | B17: Interaction utilisateur | C17: R | D17: =C17 -> R | E17: =VLOOKUP("UI:"&D17,'Aide et coefficients'!$A$15:$C$65,2,FALSE()) -> 0.62 | G17: Score de base | H17: =IF(H15<=0,0,ROUNDUP(ROUND(MIN(IF(D18="C",1.08,1)*(H15+H16),10),5),1)) -> 9.6
A18: S | B18: Portée | C18: C | D18: =C18 -> C | E18: =VLOOKUP("S:"&D18,'Aide et coefficients'!$A$15:$C$65,2,FALSE()) -> — | G18: Score temporel | H18: =ROUNDUP(ROUND(H17*E24*E25*E26,5),1) -> 9.6
A19: C | B19: Confidentialité | C19: H | D19: =C19 -> H | E19: =VLOOKUP("C:"&D19,'Aide et coefficients'!$A$15:$C$65,2,FALSE()) -> 0.56
A20: I | B20: Intégrité | C20: H | D20: =C20 -> H | E20: =VLOOKUP("I:"&D20,'Aide et coefficients'!$A$15:$C$65,2,FALSE()) -> 0.56 | G20: MISS | H20: =MIN(1-(1-E29*E39)*(1-E30*E40)*(1-E31*E41),0.915) -> 0.914816
A21: A | B21: Disponibilité | C21: H | D21: =C21 -> H | E21: =VLOOKUP("A:"&D21,'Aide et coefficients'!$A$15:$C$65,2,FALSE()) -> 0.56 | G21: Impact modifié | H21: =IF(D38="U",6.42*H20,IF(C4="CVSS 3.1",7.52*(H20-0.029)-3.25*(H20*0.9731-0.02)^13,7.52*(H20-0.029)-3.25*(H20-0.02)^15)) -> 6.1280263
A22: MÉTRIQUES TEMPORELLES | G22: Exploitabilité modifiée | H22: =8.22*E34*E35*E36*E37 -> 2.8352547
A23: Code | B23: Critère | C23: Choix | D23: Effectif | E23: Poids | G23: Sous-total environnemental plafonné | H23: =MIN(IF(D38="C",1.08,1)*(H21+H22),10) -> 9.6803435
A24: E | B24: Maturité du code | C24: x | D24: =C24 -> x | E24: =VLOOKUP("E:"&D24,'Aide et coefficients'!$A$15:$C$65,2,FALSE()) -> 1 | G24: Sous-total arrondi | H24: =ROUNDUP(ROUND(H23,5),1) -> 9.7
A25: RL | B25: Niveau de correctif | C25: X | D25: =C25 -> X | E25: =VLOOKUP("RL:"&D25,'Aide et coefficients'!$A$15:$C$65,2,FALSE()) -> 1 | G25: Score environnemental | H25: =IF(H21<=0,0,ROUNDUP(ROUND(H24*E24*E25*E26,5),1)) -> 9.7
A26: RC | B26: Fiabilité du rapport | C26: x | D26: =C26 -> x | E26: =VLOOKUP("RC:"&D26,'Aide et coefficients'!$A$15:$C$65,2,FALSE()) -> 1
A27: BESOINS DE SÉCURITÉ
A28: Code | B28: Critère | C28: Choix | D28: Effectif | E28: Poids
A29: CR | B29: Besoin de confidentialité | C29: X | D29: =C29 -> X | E29: =VLOOKUP("CR:"&D29,'Aide et coefficients'!$A$15:$C$65,2,FALSE()) -> 1
A30: IR | B30: Besoin d’intégrité | C30: X | D30: =C30 -> X | E30: =VLOOKUP("IR:"&D30,'Aide et coefficients'!$A$15:$C$65,2,FALSE()) -> 1
A31: AR | B31: Besoin de disponibilité | C31: X | D31: =C31 -> X | E31: =VLOOKUP("AR:"&D31,'Aide et coefficients'!$A$15:$C$65,2,FALSE()) -> 1
A32: MÉTRIQUES MODIFIÉES
A33: Code | B33: Critère | C33: Choix | D33: Effectif | E33: Poids
A34: MAV | B34: Modifié : Vecteur d’attaque | C34: X | D34: =IF(C34="X",D14,C34) -> N | E34: =VLOOKUP("AV:"&D34,'Aide et coefficients'!$A$15:$C$65,2,FALSE()) -> 0.85
A35: MAC | B35: Modifié : Complexité | C35: X | D35: =IF(C35="X",D15,C35) -> L | E35: =VLOOKUP("AC:"&D35,'Aide et coefficients'!$A$15:$C$65,2,FALSE()) -> 0.77 | G35: X : non défini (poids neutre ou reprise de la base).
A36: MPR | B36: Modifié : Privilèges requis | C36: X | D36: =IF(C36="X",D16,C36) -> N | E36: =VLOOKUP("PR:"&D38&":"&D36,'Aide et coefficients'!$A$15:$C$65,2,FALSE()) -> 0.85
A37: MUI | B37: Modifié : Interaction utilisateur | C37: X | D37: =IF(C37="X",D17,C37) -> R | E37: =VLOOKUP("UI:"&D37,'Aide et coefficients'!$A$15:$C$65,2,FALSE()) -> 0.62 | G37: Les trois scores ne s’additionnent pas.
A38: MS | B38: Modifié : Portée | C38: X | D38: =IF(C38="X",D18,C38) -> C | E38: =VLOOKUP("S:"&D38,'Aide et coefficients'!$A$15:$C$65,2,FALSE()) -> —
A39: MC | B39: Modifié : Confidentialité | C39: X | D39: =IF(C39="X",D19,C39) -> H | E39: =VLOOKUP("C:"&D39,'Aide et coefficients'!$A$15:$C$65,2,FALSE()) -> 0.56 | G39: Jaune = saisie ; les autres cellules sont calculées.
A40: MI | B40: Modifié : Intégrité | C40: X | D40: =IF(C40="X",D20,C40) -> H | E40: =VLOOKUP("I:"&D40,'Aide et coefficients'!$A$15:$C$65,2,FALSE()) -> 0.56
A41: MA | B41: Modifié : Disponibilité | C41: X | D41: =IF(C41="X",D21,C41) -> H | E41: =VLOOKUP("A:"&D41,'Aide et coefficients'!$A$15:$C$65,2,FALSE()) -> 0.56 | G41: Sans macro. Pas de récupération automatique sur NVD.
G44: Vecteur de base à copier
G45: ="CVSS:"&IF(C4="CVSS 3.1","3.1","3.0")&"/AV:"&C14&"/AC:"&C15&"/PR:"&C16&"/UI:"&C17&"/S:"&C18&"/C:"&C19&"/I:"&C20&"/A:"&C21 -> CVSS:3.1/AV:N/AC:L/PR:N/UI:R/S:C/C:H/I:H/A:H
...

Sheet Aide et coefficients
A2: Aide et coefficients | E2: SIGNIFICATION DES CRITÈRES
E3: AV : accès nécessaire ; AC : conditions particulières de réussite.
E4: PR : privilèges déjà requis ; UI : action d’un autre utilisateur nécessaire.
A5: PR:U = portée inchangée | E5: S : franchissement d’une autorité de sécurité (U inchangée, C changée).
A6: PR:C = portée changée | E6: C : perte de confidentialité ; I : altération ; A : perte de disponibilité.
E7: E : maturité du code ; RL : correctif disponible ; RC : fiabilité des informations.
A8: S n’a pas de poids numérique. | E8: CR / IR / AR : importance locale de la confidentialité, intégrité, disponibilité.
E9: MAV à MA : critères réévalués selon les protections et conditions locales.
A12: Poids de référence
A14: Clé | B14: Poids | C14: Signification
A15: AV:N | B15: 0.85 | C15: Réseau
A16: AV:A | B16: 0.62 | C16: Réseau adjacent
A17: AV:L | B17: 0.55 | C17: Local
A18: AV:P | B18: 0.2 | C18: Physique
A19: AC:L | B19: 0.77 | C19: Faible
A20: AC:H | B20: 0.44 | C20: Élevée
A21: UI:N | B21: 0.85 | C21: Aucune
A22: UI:R | B22: 0.62 | C22: Requise
A23: E:X | B23: 1 | C23: Non défini
A24: E:H | B24: 1 | C24: Élevée
A25: E:F | B25: 0.97 | C25: Fonctionnel
A26: E:P | B26: 0.94 | C26: Preuve de concept
... A63: PR:C:H | B63: 0.5 | C63: Élevés
A64: S:U | B64: — | C64: Inchangée
A65: S:C | B65: — | C65: Changée
